<?xml version="1.0"?>
<robot name="concept" xmlns:xacro="http://ros.org/wiki/xacro">


  <!-- constraints -->
  <!-- update these with the real dimensions later -->
  <xacro:property name="box_length" value="0.6"/>
  <xacro:property name="box_width" value="0.4"/>
  <xacro:property name="box_height" value="0.2"/>

  <xacro:property name="wheel_radius" value="0.1"/>
  <xacro:property name="wheel_length" value="0.05"/>

  <xacro:property name="caster_radius" value="0.05"/>

  <!-- Base Link -->
  <link name="base_link">
    <visual>
      <geometry>
        <box size="${box_length} ${box_width} ${box_height}"/>
      </geometry>
      <material name="blue">
        <color rgba="0 0 1 1"/>
      </material>
    </visual>
    <collision>
      <geometry>
        <box size="${box_length} ${box_width} ${box_height}"/>
      </geometry>
    </collision>
  </link>

  <!-- Motored Wheels -->
  <!-- Left Side -->
  <link name="left_wheel">
    <visual>
      <geometry>
        <cylinder radius="${wheel_radius}" length="${wheel_length}"/>
      </geometry>
    </visual>
    <collision>
      <geometry>
        <cylinder radius="${wheel_radius}" length="${wheel_length}"/>
      </geometry>
    </collision>
  </link>

  <!-- Right Side -->
  <link name="right_wheel">
    <visual>
      <geometry>
        <cylinder radius="${wheel_radius}" length="${wheel_length}"/>
      </geometry>
    </visual>
    <collision>
      <geometry>
        <cylinder radius="${wheel_radius}" length="${wheel_length}"/>
      </geometry>
    </collision>
  </link>

  <!-- Caster Wheels -->
  <!-- Front Caster -->
  <link name="front_caster">
    <visual>
      <geometry>
        <sphere radius="${caster_radius}"/>
      </geometry>
    </visual>
    <collision>
      <geometry>
        <sphere radius="${caster_radius}"/>
      </geometry>
    </collision>
  </link>

  <!-- Rear Caster -->
  <link name="rear_caster">
    <visual>
      <geometry>
        <sphere radius="${caster_radius}"/>
      </geometry>
    </visual>
    <collision>
      <geometry>
        <sphere radius="${caster_radius}"/>
      </geometry>
    </collision>
  </link>

  <!-- Joints -->
  <!-- Motored Wheel Joints -->
  <joint name="left_wheel_joint" type="continuous">
    <parent link="base_link"/>
    <child link="left_wheel"/>
    <origin xyz="0 ${(box_width/2)+(wheel_length/2)} -0.05" rpy="${pi/2} 0 0"/>
    <axis xyz="0 0 1"/>
  </joint>

  <joint name="right_wheel_joint" type="continuous">
    <parent link="base_link"/>
    <child link="right_wheel"/>
    <origin xyz="0 ${(-box_width/2)+(-wheel_length/2)} -0.05" rpy="${pi/2} 0 0"/>
    <axis xyz="0 0 1"/>
  </joint>

  <!-- Caster Wheel Joints -->
  <joint name="front_caster_joint" type="fixed">
    <parent link="base_link"/>
    <child link="front_caster"/>
    <origin xyz="0.3 0 -0.1" rpy="0 0 0"/>
  </joint>

  <joint name="rear_caster_joint" type="fixed">
    <parent link="base_link"/>
    <child link="rear_caster"/>
    <origin xyz="-0.3 0 -0.1" rpy="0 0 0"/>
  </joint>

  <!-- Robot Footprint -->
  <link name="base_footprint"/>

  <joint name="base_joint" type="fixed">
    <parent link="base_link"/>
    <child link="base_footprint"/>
    <origin xyz="0 0 -0.15" rpy="0 0 0"/>
  </joint>
</robot>